2023-03-06 23:40:13,018 INFO    MainThread:30 [wandb_setup.py:_flush():68] Configure stats pid to 30
2023-03-06 23:40:13,019 INFO    MainThread:30 [wandb_setup.py:_flush():68] Loading settings from /home/susan/.config/wandb/settings
2023-03-06 23:40:13,019 INFO    MainThread:30 [wandb_setup.py:_flush():68] Loading settings from /mnt/c/Users/susan/git/HEA-Toxicity-Prediction/wandb/settings
2023-03-06 23:40:13,019 INFO    MainThread:30 [wandb_setup.py:_flush():68] Loading settings from environment variables: {'_require_service': 'True'}
2023-03-06 23:40:13,019 INFO    MainThread:30 [wandb_setup.py:_flush():68] Inferring run settings from compute environment: {'program_relpath': 'runner.py', 'program': '/mnt/c/Users/susan/git/HEA-Toxicity-Prediction/runner.py'}
2023-03-06 23:40:13,020 INFO    MainThread:30 [wandb_init.py:_log_setup():492] Logging user logs to /mnt/c/Users/susan/git/HEA-Toxicity-Prediction/wandb/run-20230306_234012-utq8ea1y/logs/debug.log
2023-03-06 23:40:13,020 INFO    MainThread:30 [wandb_init.py:_log_setup():493] Logging internal logs to /mnt/c/Users/susan/git/HEA-Toxicity-Prediction/wandb/run-20230306_234012-utq8ea1y/logs/debug-internal.log
2023-03-06 23:40:13,020 INFO    MainThread:30 [wandb_init.py:init():532] calling init triggers
2023-03-06 23:40:13,020 INFO    MainThread:30 [wandb_init.py:init():538] wandb.init called with sweep_config: {}
config: {'batch_size': 64, 'epochs': 150, 'learning_rate': 0.002, 'architecture': 'NN', 'datset': 'Full'}
2023-03-06 23:40:13,021 INFO    MainThread:30 [wandb_init.py:init():588] starting backend
2023-03-06 23:40:13,021 INFO    MainThread:30 [wandb_init.py:init():592] setting up manager
2023-03-06 23:40:13,025 INFO    MainThread:30 [backend.py:_multiprocessing_setup():106] multiprocessing start_methods=fork,spawn,forkserver, using: spawn
2023-03-06 23:40:13,030 INFO    MainThread:30 [wandb_init.py:init():599] backend started and connected
2023-03-06 23:40:13,032 INFO    MainThread:30 [wandb_init.py:init():687] updated telemetry
2023-03-06 23:40:13,099 INFO    MainThread:30 [wandb_init.py:init():727] communicating run to backend with 60.0 second timeout
2023-03-06 23:40:41,603 INFO    Thread-1  :30 [retry.py:__call__():172] Retry attempt failed:
Traceback (most recent call last):
  File "/home/susan/miniconda3/lib/python3.9/site-packages/urllib3/connection.py", line 174, in _new_conn
    conn = connection.create_connection(
  File "/home/susan/miniconda3/lib/python3.9/site-packages/urllib3/util/connection.py", line 72, in create_connection
    for res in socket.getaddrinfo(host, port, family, socket.SOCK_STREAM):
  File "/home/susan/miniconda3/lib/python3.9/socket.py", line 954, in getaddrinfo
    for res in _socket.getaddrinfo(host, port, family, type, proto, flags):
socket.gaierror: [Errno -3] Temporary failure in name resolution

During handling of the above exception, another exception occurred:

Traceback (most recent call last):
  File "/home/susan/miniconda3/lib/python3.9/site-packages/urllib3/connectionpool.py", line 703, in urlopen
    httplib_response = self._make_request(
  File "/home/susan/miniconda3/lib/python3.9/site-packages/urllib3/connectionpool.py", line 386, in _make_request
    self._validate_conn(conn)
  File "/home/susan/miniconda3/lib/python3.9/site-packages/urllib3/connectionpool.py", line 1042, in _validate_conn
    conn.connect()
  File "/home/susan/miniconda3/lib/python3.9/site-packages/urllib3/connection.py", line 358, in connect
    self.sock = conn = self._new_conn()
  File "/home/susan/miniconda3/lib/python3.9/site-packages/urllib3/connection.py", line 186, in _new_conn
    raise NewConnectionError(
urllib3.exceptions.NewConnectionError: <urllib3.connection.HTTPSConnection object at 0x7fb8e8a44340>: Failed to establish a new connection: [Errno -3] Temporary failure in name resolution

During handling of the above exception, another exception occurred:

Traceback (most recent call last):
  File "/home/susan/.local/lib/python3.9/site-packages/requests/adapters.py", line 489, in send
    resp = conn.urlopen(
  File "/home/susan/miniconda3/lib/python3.9/site-packages/urllib3/connectionpool.py", line 787, in urlopen
    retries = retries.increment(
  File "/home/susan/miniconda3/lib/python3.9/site-packages/urllib3/util/retry.py", line 592, in increment
    raise MaxRetryError(_pool, url, error or ResponseError(cause))
urllib3.exceptions.MaxRetryError: HTTPSConnectionPool(host='api.wandb.ai', port=443): Max retries exceeded with url: /graphql (Caused by NewConnectionError('<urllib3.connection.HTTPSConnection object at 0x7fb8e8a44340>: Failed to establish a new connection: [Errno -3] Temporary failure in name resolution'))

During handling of the above exception, another exception occurred:

Traceback (most recent call last):
  File "/home/susan/miniconda3/lib/python3.9/site-packages/wandb/sdk/lib/retry.py", line 131, in __call__
    result = self._call_fn(*args, **kwargs)
  File "/home/susan/miniconda3/lib/python3.9/site-packages/wandb/sdk/internal/internal_api.py", line 242, in execute
    return self.client.execute(*args, **kwargs)  # type: ignore
  File "/home/susan/miniconda3/lib/python3.9/site-packages/wandb/vendor/gql-0.2.0/wandb_gql/client.py", line 52, in execute
    result = self._get_result(document, *args, **kwargs)
  File "/home/susan/miniconda3/lib/python3.9/site-packages/wandb/vendor/gql-0.2.0/wandb_gql/client.py", line 60, in _get_result
    return self.transport.execute(document, *args, **kwargs)
  File "/home/susan/miniconda3/lib/python3.9/site-packages/wandb/vendor/gql-0.2.0/wandb_gql/transport/requests.py", line 38, in execute
    request = requests.post(self.url, **post_args)
  File "/home/susan/.local/lib/python3.9/site-packages/requests/api.py", line 115, in post
    return request("post", url, data=data, json=json, **kwargs)
  File "/home/susan/.local/lib/python3.9/site-packages/requests/api.py", line 59, in request
    return session.request(method=method, url=url, **kwargs)
  File "/home/susan/.local/lib/python3.9/site-packages/requests/sessions.py", line 587, in request
    resp = self.send(prep, **send_kwargs)
  File "/home/susan/.local/lib/python3.9/site-packages/requests/sessions.py", line 701, in send
    r = adapter.send(request, **kwargs)
  File "/home/susan/.local/lib/python3.9/site-packages/requests/adapters.py", line 565, in send
    raise ConnectionError(e, request=request)
requests.exceptions.ConnectionError: HTTPSConnectionPool(host='api.wandb.ai', port=443): Max retries exceeded with url: /graphql (Caused by NewConnectionError('<urllib3.connection.HTTPSConnection object at 0x7fb8e8a44340>: Failed to establish a new connection: [Errno -3] Temporary failure in name resolution'))
